Workbook

Sheet Dashboard
A1: ClinicShift Roster — Dashboard
A2: Bright Smiles Clinic (edit clinic name on Read Me First)
A4: Reference Date: | B4: 46301 | C4: (must fall inside the Monthly Roster month)
A6: Total Employees | D6: Working Today | G6: Weekly Off Today
A7: =COUNTA('Staff Master'!A5:A24) -> 20 | D7: =SUMPRODUCT(('Monthly Roster'!$A$5:$A$624=$B$4)*('Monthly Roster'!$K$5:$K$624>0)) -> 18 | G7: =COUNTIFS('Monthly Roster'!$A$5:$A$624,$B$4,'Monthly Roster'!$G$5:$G$624,"OFF") -> 1
A9: Annual Leave Today | D9: Sick Leave Today | G9: Other Leave Today
A10: =COUNTIFS('Monthly Roster'!$A$5:$A$624,$B$4,'Monthly Roster'!$G$5:$G$624,"AL") -> 1 | D10: =COUNTIFS('Monthly Roster'!$A$5:$A$624,$B$4,'Monthly Roster'!$G$5:$G$624,"SL") -> 0 | G10: =SUMPRODUCT(('Monthly Roster'!$A$5:$A$624=$B$4)*((('Monthly Roster'!$G$5:$G$624="EL")+('Monthly Roster'!$G$5:$G$624="UL")+('Monthly Roster'!$G$5:$G$624="OL")+('Monthly Roster'!$G$5:$G$624="PH")))) -> 0
A12: Pending Shift Requests | D12: Pending HR Approvals | G12: Staffing Shortages Today
A13: =COUNTIFS('Shift Change Requests'!O:O,"Submitted")+COUNTIFS('Shift Change Requests'!O:O,"Pending Manager")+COUNTIFS('Shift Change Requests'!O:O,"Pending HR") -> 1 | D13: =COUNTIFS('Leave Register'!J:J,"Pending")+COUNTIFS('Shift Change Requests'!O:O,"Pending HR") -> 1 | G13: =COUNTIFS('Monthly Roster'!$A$5:$A$624,$B$4,'Monthly Roster'!$N$5:$N$624,"SHORT") -> 1

Sheet Read Me First
A1: ClinicShift Roster — Excel Template
A2: Cloud-based clinic staff shift roster & HR approval workflow, adapted for Excel
A4: How to use this workbook
A5: 1. Staff Master, Department Master, Position Master and Shift Master are your configuration tables — edit them first for your own clinic.
A6: 2. Monthly Roster is pre-filled with one demo month (October 2026) for 20 sample employees. Yellow cells are the ones you are meant to edit; everything else is a formula.
A7: 3. Change the 'Reference Date' cell on the Dashboard sheet to any date inside the roster month to see that day's staffing counts update.
A8: 4. Leave Register, Shift Change Requests and Change Log are logs — add a new row for each new leave, request or change; update the Monthly Roster shift code by hand once something is approved (this workbook is a record-keeping template, not a live app).
A9: 5. Staffing Coverage lists your minimum-staff rules; Monthly Roster column M flags any date/shift below that minimum with a formula.
A10: 6. Monthly Summary and Dashboard total everything else with formulas (SUMIFS/COUNTIFS) — extend the ranges if you add more rows or months.
A11: 7. Cells shaded pale yellow with blue text are inputs meant to be edited; black text is a formula — do not overtype it.
A12: 8. For a live, multi-user version with roles, approvals and a shared database, see the ClinicShift Roster web app version of this template.
A14: Legend
A15: Editable input | B15: Formula — do not overtype

Sheet Department Master
A1: Department Master
A2: Add or edit clinic departments here
A4: Dept ID | B4: Department Name | C4: Manager / Supervisor
A5: DEP-MGMT | B5: Management | C5: Rashid Al Nuaimi
A6: DEP-ADMIN | B6: Administration | C6: Meera Pillai
A7: DEP-HR | B7: HR | C7: Meera Pillai
A8: DEP-RECEPTION | B8: Reception | C8: Meera Pillai
A9: DEP-DENTAL | B9: Dental | C9: Dr. Sara Haddad
A10: DEP-NURSING | B10: Nursing | C10: Dr. Sara Haddad
A11: DEP-GP | B11: General Practice | C11: Dr. Sara Haddad
A12: DEP-LASER | B12: Laser | C12: Dr. Sara Haddad
A13: DEP-CSSD | B13: CSSD | C13: Meera Pillai
A14: DEP-DENTALLAB | B14: Dental Laboratory | C14: Dr. Sara Haddad
A15: DEP-CLEANING | B15: Cleaning | C15: Hassan Baig
A16: DEP-FACILITIES | B16: Facilities | C16: Hassan Baig

Sheet Position Master
A1: Position Master
A2: Add or edit job positions here
A4: Position Name
A5: CEO
A6: Medical Director
A7: Doctor
A8: Dentist
A9: General Practitioner
A10: Nurse
A11: Receptionist
A12: Dental Assistant
A13: Laser Technician
... A19: Admin Staff

Sheet Shift Master
A1: Shift Master
A2: Fully configurable — change times freely, hours recalculate automatically
A4: Shift Code | B4: Shift Name | C4: Start | D4: End | E4: Break (min) | F4: Working Shift? | G4: Working Hours
A5: M1 | B5: Morning | C5: 0.33333333 | D5: 0.70833333 | E5: 60 | F5: Yes | G5: =IF(F5="Yes",ROUND((D5-C5)*24-E5/60,2),0) -> 8
A6: M2 | B6: Day | C6: 0.375 | D6: 0.75 | E6: 60 | F6: Yes | G6: =IF(F6="Yes",ROUND((D6-C6)*24-E6/60,2),0) -> 8
A7: M3 | B7: Extended Day | C7: 0.41666667 | D7: 0.79166667 | E7: 60 | F7: Yes | G7: =IF(F7="Yes",ROUND((D7-C7)*24-E7/60,2),0) -> 8
A8: E1 | B8: Evening | C8: 0.54166667 | D8: 0.91666667 | E8: 60 | F8: Yes | G8: =IF(F8="Yes",ROUND((D8-C8)*24-E8/60,2),0) -> 8
A9: D1 | B9: Doctor | C9: 0.375 | D9: 0.70833333 | E9: 60 | F9: Yes | G9: =IF(F9="Yes",ROUND((D9-C9)*24-E9/60,2),0) -> 7
A10: OFF | B10: Weekly Off | E10: 0 | F10: No | G10: =IF(F10="Yes",ROUND((D10-C10)*24-E10/60,2),0) -> 0
A11: AL | B11: Annual Leave | E11: 0 | F11: No | G11: =IF(F11="Yes",ROUND((D11-C11)*24-E11/60,2),0) -> 0
A12: SL | B12: Sick Leave | E12: 0 | F12: No | G12: =IF(F12="Yes",ROUND((D12-C12)*24-E12/60,2),0) -> 0
A13: EL | B13: Emergency Leave | E13: 0 | F13: No | G13: =IF(F13="Yes",ROUND((D13-C13)*24-E13/60,2),0) -> 0
A14: UL | B14: Unpaid Leave | E14: 0 | F14: No | G14: =IF(F14="Yes",ROUND((D14-C14)*24-E14/60,2),0) -> 0
A15: OL | B15: Other Leave | E15: 0 | F15: No | G15: =IF(F15="Yes",ROUND((D15-C15)*24-E15/60,2),0) -> 0
A16: PH | B16: Public Holiday | E16: 0 | F16: No | G16: =IF(F16="Yes",ROUND((D16-C16)*24-E16/60,2),0) -> 0

Sheet Staff Master
A1: Staff Master
A2: Confidential — remarks & contact details intended for HR eyes only
A4: Employee ID | B4: Name | C4: Gender | D4: Department | E4: Position | F4: Employment Type | G4: Joining Date | H4: Work Location | I4: Mobile | J4: Email | K4: Manager | L4: Standard Shift | M4: Weekly Off | N4: Employment Status | O4: Remarks
A5: EMP001 | B5: Rashid Al Nuaimi | C5: M | D5: Management | E5: CEO | F5: Full-time | G5: 43471 | H5: Main Clinic | I5: 0501234001 | J5: rashid.alnuaimi@clinic.ae | K5: — | L5: M2 | M5: Sat | N5: Active
A6: EMP002 | B6: Dr. Sara Haddad | C6: F | D6: General Practice | E6: Medical Director | F6: Full-time | G6: 43535 | H6: Main Clinic | I6: 0501234002 | J6: sara.haddad@clinic.ae | K6: EMP001 | L6: D1 | M6: Fri | N6: Active
A7: EMP003 | B7: Dr. Omar Khalil | C7: M | D7: General Practice | E7: Doctor | F7: Full-time | G7: 43862 | H7: Main Clinic | I7: 0501234003 | J7: omar.khalil@clinic.ae | K7: EMP002 | L7: D1 | M7: Sat | N7: Active
A8: EMP004 | B8: Dr. Lina Abboud | C8: F | D8: Dental | E8: Dentist | F8: Full-time | G8: 43997 | H8: Main Clinic | I8: 0501234004 | J8: lina.abboud@clinic.ae | K8: EMP002 | L8: D1 | M8: Fri | N8: Active
A9: EMP005 | B9: Dr. Farah Idris | C9: F | D9: Dental | E9: Dentist | F9: Part-time | G9: 44440 | H9: Main Clinic | I9: 0501234005 | J9: farah.idris@clinic.ae | K9: EMP002 | L9: D1 | M9: Sun | N9: Active | O9: Part-time — 3 days/week
A10: EMP006 | B10: Dr. Youssef Nassar | C10: M | D10: General Practice | E10: General Practitioner | F10: Full-time | G10: 44206 | H10: Main Clinic | I10: 0501234006 | J10: youssef.nassar@clinic.ae | K10: EMP002 | L10: D1 | M10: Sat | N10: Active
A11: EMP007 | B11: Grace Fernandez | C11: F | D11: Nursing | E11: Nurse | F11: Full-time | G11: 43697 | H11: Main Clinic | I11: 0501234007 | J11: grace.fernandez@clinic.ae | K11: EMP002 | L11: M1 | M11: Sun | N11: Active
A12: EMP008 | B12: Priya Nair | C12: F | D12: Nursing | E12: Nurse | F12: Full-time | G12: 43956 | H12: Main Clinic | I12: 0501234008 | J12: priya.nair@clinic.ae | K12: EMP002 | L12: M2 | M12: Mon | N12: Active
A13: EMP009 | B13: Maria Santos | C13: F | D13: Nursing | E13: Nurse | F13: Full-time | G13: 44512 | H13: Main Clinic | I13: 0501234009 | J13: maria.santos@clinic.ae | K13: EMP002 | L13: E1 | M13: Sat | N13: Active
A14: EMP010 | B14: Aisha Al Shamsi | C14: F | D14: Reception | E14: Receptionist | F14: Full-time | G14: 43573 | H14: Main Clinic | I14: 0501234010 | J14: aisha.alshamsi@clinic.ae | K14: EMP020 | L14: M1 | M14: Mon | N14: Active
A15: EMP011 | B15: John Dsouza | C15: M | D15: Reception | E15: Receptionist | F15: Full-time | G15: 44083 | H15: Main Clinic | I15: 0501234011 | J15: john.dsouza@clinic.ae | K15: EMP020 | L15: M2 | M15: Tue | N15: Active
A16: EMP012 | B16: Fatima Zahra | C16: F | D16: Reception | E16: Receptionist | F16: Full-time | G16: 44584 | H16: Main Clinic | I16: 0501234012 | J16: fatima.zahra@clinic.ae | K16: EMP020 | L16: E1 | M16: Sat | N16: Active
A17: EMP013 | B17: Ana Reyes | C17: F | D17: Dental | E17: Dental Assistant | F17: Full-time | G17: 43892 | H17: Main Clinic | I17: 0501234013 | J17: ana.reyes@clinic.ae | K17: EMP004 | L17: M1 | M17: Sun | N17: Active
A18: EMP014 | B18: Noor Hassan | C18: F | D18: Dental | E18: Dental Assistant | F18: Full-time | G18: 44396 | H18: Main Clinic | I18: 0501234014 | J18: noor.hassan@clinic.ae | K18: EMP004 | L18: M2 | M18: Sat | N18: Active
A19: EMP015 | B19: Karan Mehta | C19: M | D19: Laser | E19: Laser Technician | F19: Full-time | G19: 44241 | H19: Main Clinic | I19: 0501234015 | J19: karan.mehta@clinic.ae | K19: EMP002 | L19: M2 | M19: Fri | N19: Active
A20: EMP016 | B20: Imran Sheikh | C20: M | D20: Dental Laboratory | E20: Dental Technician | F20: Full-time | G20: 43800 | H20: Main Clinic | I20: 0501234016 | J20: imran.sheikh@clinic.ae | K20: EMP004 | L20: M1 | M20: Sat | N20: Active
A21: EMP017 | B21: Josephine Cruz | C21: F | D21: CSSD | E21: CSSD Technician | F21: Full-time | G21: 44110 | H21: Main Clinic | I21: 0501234017 | J21: josephine.cruz@clinic.ae | K21: EMP020 | L21: M1 | M21: Sun | N21: Active
... A24: EMP020 | B24: Meera Pillai | C24: F | D24: HR | E24: HR Executive | F24: Full-time | G24: 43845 | H24: Main Clinic | I24: 0501234020 | J24: meera.pillai@clinic.ae | K24: EMP001 | L24: M2 | M24: Sat | N24: Active

Sheet Staffing Coverage
A1: Staffing Coverage
A2: Minimum required staff per department & shift
A4: Department | B4: Shift Code | C4: Minimum Required
A5: Reception | B5: M1 | C5: 2
A6: Reception | B6: M2 | C6: 2
A7: Reception | B7: E1 | C7: 1
A8: Nursing | B8: M1 | C8: 1
A9: Nursing | B9: M2 | C9: 1
A10: Cleaning | B10: M1 | C10: 1
A11: CSSD | B11: M1 | C11: 1
A12: Dental | B12: M1 | C12: 1

Sheet Monthly Roster
A1: Monthly Roster — October 2026
A2: Shift codes are editable (yellow); every other column is a lookup formula
A4: Date | B4: Day | C4: Employee ID | D4: Employee | E4: Department | F4: Position | G4: Shift Code | H4: Start | I4: End | J4: Break (min) | K4: Hours | L4: Status | M4: HR Confirmation | N4: Shortage Flag
A5: 46296 | B5: =TEXT(A5,"ddd") -> Thu | C5: EMP001 | D5: =IFERROR(INDEX('Staff Master'!$B$5:$B$24,MATCH(C5,'Staff Master'!$A$5:$A$24,0)),"") -> Rashid Al Nuaimi | E5: =IFERROR(INDEX('Staff Master'!$D$5:$D$24,MATCH(C5,'Staff Master'!$A$5:$A$24,0)),"") -> Management | F5: =IFERROR(INDEX('Staff Master'!$E$5:$E$24,MATCH(C5,'Staff Master'!$A$5:$A$24,0)),"") -> CEO | G5: M2 | H5: =IFERROR(INDEX('Shift Master'!$C$5:$C$16,MATCH(G5,'Shift Master'!$A$5:$A$16,0)),"") -> 0.375 | I5: =IFERROR(INDEX('Shift Master'!$D$5:$D$16,MATCH(G5,'Shift Master'!$A$5:$A$16,0)),"") -> 0.75 | J5: =IFERROR(INDEX('Shift Master'!$E$5:$E$16,MATCH(G5,'Shift Master'!$A$5:$A$16,0)),"") -> 60 | K5: =IFERROR(INDEX('Shift Master'!$G$5:$G$16,MATCH(G5,'Shift Master'!$A$5:$A$16,0)),0) -> 8 | L5: FINAL – HR CONFIRMED | M5: CONFIRMED | N5: =IF(COUNTIFS('Staffing Coverage'!$A$5:$A$12,E5,'Staffing Coverage'!$B$5:$B$12,G5)=0,"",IF(COUNTIFS($A$5:$A$10004,A5,$E$5:$E$10004,E5,$G$5:$G$10004,G5)<INDEX('Staffing Coverage'!$C$5:$C$12,MATCH(1,('Staffing Coverage'!$A$5:$A$12=E5)*('Staffing Coverage'!$B$5:$B$12=G5),0)),"SHORT","OK"))
A6: 46296 | B6: =TEXT(A6,"ddd") -> Thu | C6: EMP002 | D6: =IFERROR(INDEX('Staff Master'!$B$5:$B$24,MATCH(C6,'Staff Master'!$A$5:$A$24,0)),"") -> Dr. Sara Haddad | E6: =IFERROR(INDEX('Staff Master'!$D$5:$D$24,MATCH(C6,'Staff Master'!$A$5:$A$24,0)),"") -> General Practice | F6: =IFERROR(INDEX('Staff Master'!$E$5:$E$24,MATCH(C6,'Staff Master'!$A$5:$A$24,0)),"") -> Medical Director | G6: D1 | H6: =IFERROR(INDEX('Shift Master'!$C$5:$C$16,MATCH(G6,'Shift Master'!$A$5:$A$16,0)),"") -> 0.375 | I6: =IFERROR(INDEX('Shift Master'!$D$5:$D$16,MATCH(G6,'Shift Master'!$A$5:$A$16,0)),"") -> 0.70833333 | J6: =IFERROR(INDEX('Shift Master'!$E$5:$E$16,MATCH(G6,'Shift Master'!$A$5:$A$16,0)),"") -> 60 | K6: =IFERROR(INDEX('Shift Master'!$G$5:$G$16,MATCH(G6,'Shift Master'!$A$5:$A$16,0)),0) -> 7 | L6: FINAL – HR CONFIRMED | M6: CONFIRMED | N6: =IF(COUNTIFS('Staffing Coverage'!$A$5:$A$12,E6,'Staffing Coverage'!$B$5:$B$12,G6)=0,"",IF(COUNTIFS($A$5:$A$10004,A6,$E$5:$E$10004,E6,$G$5:$G$10004,G6)<INDEX('Staffing Coverage'!$C$5:$C$12,MATCH(1,('Staffing Coverage'!$A$5:$A$12=E6)*('Staffing Coverage'!$B$5:$B$12=G6),0)),"SHORT","OK"))
A7: 46296 | B7: =TEXT(A7,"ddd") -> Thu | C7: EMP003 | D7: =IFERROR(INDEX('Staff Master'!$B$5:$B$24,MATCH(C7,'Staff Master'!$A$5:$A$24,0)),"") -> Dr. Omar Khalil | E7: =IFERROR(INDEX('Staff Master'!$D$5:$D$24,MATCH(C7,'Staff Master'!$A$5:$A$24,0)),"") -> General Practice | F7: =IFERROR(INDEX('Staff Master'!$E$5:$E$24,MATCH(C7,'Staff Master'!$A$5:$A$24,0)),"") -> Doctor | G7: D1 | H7: =IFERROR(INDEX('Shift Master'!$C$5:$C$16,MATCH(G7,'Shift Master'!$A$5:$A$16,0)),"") -> 0.375 | I7: =IFERROR(INDEX('Shift Master'!$D$5:$D$16,MATCH(G7,'Shift Master'!$A$5:$A$16,0)),"") -> 0.70833333 | J7: =IFERROR(INDEX('Shift Master'!$E$5:$E$16,MATCH(G7,'Shift Master'!$A$5:$A$16,0)),"") -> 60 | K7: =IFERROR(INDEX('Shift Master'!$G$5:$G$16,MATCH(G7,'Shift Master'!$A$5:$A$16,0)),0) -> 7 | L7: FINAL – HR CONFIRMED | M7: CONFIRMED | N7: =IF(COUNTIFS('Staffing Coverage'!$A$5:$A$12,E7,'Staffing Coverage'!$B$5:$B$12,G7)=0,"",IF(COUNTIFS($A$5:$A$10004,A7,$E$5:$E$10004,E7,$G$5:$G$10004,G7)<INDEX('Staffing Coverage'!$C$5:$C$12,MATCH(1,('Staffing Coverage'!$A$5:$A$12=E7)*('Staffing Coverage'!$B$5:$B$12=G7),0)),"SHORT","OK"))
A8: 46296 | B8: =TEXT(A8,"ddd") -> Thu | C8: EMP004 | D8: =IFERROR(INDEX('Staff Master'!$B$5:$B$24,MATCH(C8,'Staff Master'!$A$5:$A$24,0)),"") -> Dr. Lina Abboud | E8: =IFERROR(INDEX('Staff Master'!$D$5:$D$24,MATCH(C8,'Staff Master'!$A$5:$A$24,0)),"") -> Dental | F8: =IFERROR(INDEX('Staff Master'!$E$5:$E$24,MATCH(C8,'Staff Master'!$A$5:$A$24,0)),"") -> Dentist | G8: D1 | H8: =IFERROR(INDEX('Shift Master'!$C$5:$C$16,MATCH(G8,'Shift Master'!$A$5:$A$16,0)),"") -> 0.375 | I8: =IFERROR(INDEX('Shift Master'!$D$5:$D$16,MATCH(G8,'Shift Master'!$A$5:$A$16,0)),"") -> 0.70833333 | J8: =IFERROR(INDEX('Shift Master'!$E$5:$E$16,MATCH(G8,'Shift Master'!$A$5:$A$16,0)),"") -> 60 | K8: =IFERROR(INDEX('Shift Master'!$G$5:$G$16,MATCH(G8,'Shift Master'!$A$5:$A$16,0)),0) -> 7 | L8: FINAL – HR CONFIRMED | M8: CONFIRMED | N8: =IF(COUNTIFS('Staffing Coverage'!$A$5:$A$12,E8,'Staffing Coverage'!$B$5:$B$12,G8)=0,"",IF(COUNTIFS($A$5:$A$10004,A8,$E$5:$E$10004,E8,$G$5:$G$10004,G8)<INDEX('Staffing Coverage'!$C$5:$C$12,MATCH(1,('Staffing Coverage'!$A$5:$A$12=E8)*('Staffing Coverage'!$B$5:$B$12=G8),0)),"SHORT","OK"))
A9: 46296 | B9: =TEXT(A9,"ddd") -> Thu | C9: EMP005 | D9: =IFERROR(INDEX('Staff Master'!$B$5:$B$24,MATCH(C9,'Staff Master'!$A$5:$A$24,0)),"") -> Dr. Farah Idris | E9: =IFERROR(INDEX('Staff Master'!$D$5:$D$24,MATCH(C9,'Staff Master'!$A$5:$A$24,0)),"") -> Dental | F9: =IFERROR(INDEX('Staff Master'!$E$5:$E$24,MATCH(C9,'Staff Master'!$A$5:$A$24,0)),"") -> Dentist | G9: D1 | H9: =IFERROR(INDEX('Shift Master'!$C$5:$C$16,MATCH(G9,'Shift Master'!$A$5:$A$16,0)),"") -> 0.375 | I9: =IFERROR(INDEX('Shift Master'!$D$5:$D$16,MATCH(G9,'Shift Master'!$A$5:$A$16,0)),"") -> 0.70833333 | J9: =IFERROR(INDEX('Shift Master'!$E$5:$E$16,MATCH(G9,'Shift Master'!$A$5:$A$16,0)),"") -> 60 | K9: =IFERROR(INDEX('Shift Master'!$G$5:$G$16,MATCH(G9,'Shift Master'!$A$5:$A$16,0)),0) -> 7 | L9: FINAL – HR CONFIRMED | M9: CONFIRMED | N9: =IF(COUNTIFS('Staffing Coverage'!$A$5:$A$12,E9,'Staffing Coverage'!$B$5:$B$12,G9)=0,"",IF(COUNTIFS($A$5:$A$10004,A9,$E$5:$E$10004,E9,$G$5:$G$10004,G9)<INDEX('Staffing Coverage'!$C$5:$C$12,MATCH(1,('Staffing Coverage'!$A$5:$A$12=E9)*('Staffing Coverage'!$B$5:$B$12=G9),0)),"SHORT","OK"))
A10: 46296 | B10: =TEXT(A10,"ddd") -> Thu | C10: EMP006 | D10: =IFERROR(INDEX('Staff Master'!$B$5:$B$24,MATCH(C10,'Staff Master'!$A$5:$A$24,0)),"") -> Dr. Youssef Nassar | E10: =IFERROR(INDEX('Staff Master'!$D$5:$D$24,MATCH(C10,'Staff Master'!$A$5:$A$24,0)),"") -> General Practice | F10: =IFERROR(INDEX('Staff Master'!$E$5:$E$24,MATCH(C10,'Staff Master'!$A$5:$A$24,0)),"") -> General Practitioner | G10: D1 | H10: =IFERROR(INDEX('Shift Master'!$C$5:$C$16,MATCH(G10,'Shift Master'!$A$5:$A$16,0)),"") -> 0.375 | I10: =IFERROR(INDEX('Shift Master'!$D$5:$D$16,MATCH(G10,'Shift Master'!$A$5:$A$16,0)),"") -> 0.70833333 | J10: =IFERROR(INDEX('Shift Master'!$E$5:$E$16,MATCH(G10,'Shift Master'!$A$5:$A$16,0)),"") -> 60 | K10: =IFERROR(INDEX('Shift Master'!$G$5:$G$16,MATCH(G10,'Shift Master'!$A$5:$A$16,0)),0) -> 7 | L10: FINAL – HR CONFIRMED | M10: CONFIRMED | N10: =IF(COUNTIFS('Staffing Coverage'!$A$5:$A$12,E10,'Staffing Coverage'!$B$5:$B$12,G10)=0,"",IF(COUNTIFS($A$5:$A$10004,A10,$E$5:$E$10004,E10,$G$5:$G$10004,G10)<INDEX('Staffing Coverage'!$C$5:$C$12,MATCH(1,('Staffing Coverage'!$A$5:$A$12=E10)*('Staffing Coverage'!$B$5:$B$12=G10),0)),"SHORT","OK"))
A11: 46296 | B11: =TEXT(A11,"ddd") -> Thu | C11: EMP007 | D11: =IFERROR(INDEX('Staff Master'!$B$5:$B$24,MATCH(C11,'Staff Master'!$A$5:$A$24,0)),"") -> Grace Fernandez | E11: =IFERROR(INDEX('Staff Master'!$D$5:$D$24,MATCH(C11,'Staff Master'!$A$5:$A$24,0)),"") -> Nursing | F11: =IFERROR(INDEX('Staff Master'!$E$5:$E$24,MATCH(C11,'Staff Master'!$A$5:$A$24,0)),"") -> Nurse | G11: M1 | H11: =IFERROR(INDEX('Shift Master'!$C$5:$C$16,MATCH(G11,'Shift Master'!$A$5:$A$16,0)),"") -> 0.33333333 | I11: =IFERROR(INDEX('Shift Master'!$D$5:$D$16,MATCH(G11,'Shift Master'!$A$5:$A$16,0)),"") -> 0.70833333 | J11: =IFERROR(INDEX('Shift Master'!$E$5:$E$16,MATCH(G11,'Shift Master'!$A$5:$A$16,0)),"") -> 60 | K11: =IFERROR(INDEX('Shift Master'!$G$5:$G$16,MATCH(G11,'Shift Master'!$A$5:$A$16,0)),0) -> 8 | L11: FINAL – HR CONFIRMED | M11: CONFIRMED | N11: =IF(COUNTIFS('Staffing Coverage'!$A$5:$A$12,E11,'Staffing Coverage'!$B$5:$B$12,G11)=0,"",IF(COUNTIFS($A$5:$A$10004,A11,$E$5:$E$10004,E11,$G$5:$G$10004,G11)<INDEX('Staffing Coverage'!$C$5:$C$12,MATCH(1,('Staffing Coverage'!$A$5:$A$12=E11)*('Staffing Coverage'!$B$5:$B$12=G11),0)),"SHORT","OK")) -> OK
A12: 46296 | B12: =TEXT(A12,"ddd") -> Thu | C12: EMP008 | D12: =IFERROR(INDEX('Staff Master'!$B$5:$B$24,MATCH(C12,'Staff Master'!$A$5:$A$24,0)),"") -> Priya Nair | E12: =IFERROR(INDEX('Staff Master'!$D$5:$D$24,MATCH(C12,'Staff Master'!$A$5:$A$24,0)),"") -> Nursing | F12: =IFERROR(INDEX('Staff Master'!$E$5:$E$24,MATCH(C12,'Staff Master'!$A$5:$A$24,0)),"") -> Nurse | G12: M2 | H12: =IFERROR(INDEX('Shift Master'!$C$5:$C$16,MATCH(G12,'Shift Master'!$A$5:$A$16,0)),"") -> 0.375 | I12: =IFERROR(INDEX('Shift Master'!$D$5:$D$16,MATCH(G12,'Shift Master'!$A$5:$A$16,0)),"") -> 0.75 | J12: =IFERROR(INDEX('Shift Master'!$E$5:$E$16,MATCH(G12,'Shift Master'!$A$5:$A$16,0)),"") -> 60 | K12: =IFERROR(INDEX('Shift Master'!$G$5:$G$16,MATCH(G12,'Shift Master'!$A$5:$A$16,0)),0) -> 8 | L12: FINAL – HR CONFIRMED | M12: CONFIRMED | N12: =IF(COUNTIFS('Staffing Coverage'!$A$5:$A$12,E12,'Staffing Coverage'!$B$5:$B$12,G12)=0,"",IF(COUNTIFS($A$5:$A$10004,A12,$E$5:$E$10004,E12,$G$5:$G$10004,G12)<INDEX('Staffing Coverage'!$C$5:$C$12,MATCH(1,('Staffing Coverage'!$A$5:$A$12=E12)*('Staffing Coverage'!$B$5:$B$12=G12),0)),"SHORT","OK")) -> OK
A13: 46296 | B13: =TEXT(A13,"ddd") -> Thu | C13: EMP009 | D13: =IFERROR(INDEX('Staff Master'!$B$5:$B$24,MATCH(C13,'Staff Master'!$A$5:$A$24,0)),"") -> Maria Santos | E13: =IFERROR(INDEX('Staff Master'!$D$5:$D$24,MATCH(C13,'Staff Master'!$A$5:$A$24,0)),"") -> Nursing | F13: =IFERROR(INDEX('Staff Master'!$E$5:$E$24,MATCH(C13,'Staff Master'!$A$5:$A$24,0)),"") -> Nurse | G13: E1 | H13: =IFERROR(INDEX('Shift Master'!$C$5:$C$16,MATCH(G13,'Shift Master'!$A$5:$A$16,0)),"") -> 0.54166667 | I13: =IFERROR(INDEX('Shift Master'!$D$5:$D$16,MATCH(G13,'Shift Master'!$A$5:$A$16,0)),"") -> 0.91666667 | J13: =IFERROR(INDEX('Shift Master'!$E$5:$E$16,MATCH(G13,'Shift Master'!$A$5:$A$16,0)),"") -> 60 | K13: =IFERROR(INDEX('Shift Master'!$G$5:$G$16,MATCH(G13,'Shift Master'!$A$5:$A$16,0)),0) -> 8 | L13: FINAL – HR CONFIRMED | M13: CONFIRMED | N13: =IF(COUNTIFS('Staffing Coverage'!$A$5:$A$12,E13,'Staffing Coverage'!$B$5:$B$12,G13)=0,"",IF(COUNTIFS($A$5:$A$10004,A13,$E$5:$E$10004,E13,$G$5:$G$10004,G13)<INDEX('Staffing Coverage'!$C$5:$C$12,MATCH(1,('Staffing Coverage'!$A$5:$A$12=E13)*('Staffing Coverage'!$B$5:$B$12=G13),0)),"SHORT","OK"))
A14: 46296 | B14: =TEXT(A14,"ddd") -> Thu | C14: EMP010 | D14: =IFERROR(INDEX('Staff Master'!$B$5:$B$24,MATCH(C14,'Staff Master'!$A$5:$A$24,0)),"") -> Aisha Al Shamsi | E14: =IFERROR(INDEX('Staff Master'!$D$5:$D$24,MATCH(C14,'Staff Master'!$A$5:$A$24,0)),"") -> Reception | F14: =IFERROR(INDEX('Staff Master'!$E$5:$E$24,MATCH(C14,'Staff Master'!$A$5:$A$24,0)),"") -> Receptionist | G14: M1 | H14: =IFERROR(INDEX('Shift Master'!$C$5:$C$16,MATCH(G14,'Shift Master'!$A$5:$A$16,0)),"") -> 0.33333333 | I14: =IFERROR(INDEX('Shift Master'!$D$5:$D$16,MATCH(G14,'Shift Master'!$A$5:$A$16,0)),"") -> 0.70833333 | J14: =IFERROR(INDEX('Shift Master'!$E$5:$E$16,MATCH(G14,'Shift Master'!$A$5:$A$16,0)),"") -> 60 | K14: =IFERROR(INDEX('Shift Master'!$G$5:$G$16,MATCH(G14,'Shift Master'!$A$5:$A$16,0)),0) -> 8 | L14: FINAL – HR CONFIRMED | M14: CONFIRMED | N14: =IF(COUNTIFS('Staffing Coverage'!$A$5:$A$12,E14,'Staffing Coverage'!$B$5:$B$12,G14)=0,"",IF(COUNTIFS($A$5:$A$10004,A14,$E$5:$E$10004,E14,$G$5:$G$10004,G14)<INDEX('Staffing Coverage'!$C$5:$C$12,MATCH(1,('Staffing Coverage'!$A$5:$A$12=E14)*('Staffing Coverage'!$B$5:$B$12=G14),0)),"SHORT","OK")) -> SHORT
A15: 46296 | B15: =TEXT(A15,"ddd") -> Thu | C15: EMP011 | D15: =IFERROR(INDEX('Staff Master'!$B$5:$B$24,MATCH(C15,'Staff Master'!$A$5:$A$24,0)),"") -> John Dsouza | E15: =IFERROR(INDEX('Staff Master'!$D$5:$D$24,MATCH(C15,'Staff Master'!$A$5:$A$24,0)),"") -> Reception | F15: =IFERROR(INDEX('Staff Master'!$E$5:$E$24,MATCH(C15,'Staff Master'!$A$5:$A$24,0)),"") -> Receptionist | G15: M2 | H15: =IFERROR(INDEX('Shift Master'!$C$5:$C$16,MATCH(G15,'Shift Master'!$A$5:$A$16,0)),"") -> 0.375 | I15: =IFERROR(INDEX('Shift Master'!$D$5:$D$16,MATCH(G15,'Shift Master'!$A$5:$A$16,0)),"") -> 0.75 | J15: =IFERROR(INDEX('Shift Master'!$E$5:$E$16,MATCH(G15,'Shift Master'!$A$5:$A$16,0)),"") -> 60 | K15: =IFERROR(INDEX('Shift Master'!$G$5:$G$16,MATCH(G15,'Shift Master'!$A$5:$A$16,0)),0) -> 8 | L15: FINAL – HR CONFIRMED | M15: CONFIRMED | N15: =IF(COUNTIFS('Staffing Coverage'!$A$5:$A$12,E15,'Staffing Coverage'!$B$5:$B$12,G15)=0,"",IF(COUNTIFS($A$5:$A$10004,A15,$E$5:$E$10004,E15,$G$5:$G$10004,G15)<INDEX('Staffing Coverage'!$C$5:$C$12,MATCH(1,('Staffing Coverage'!$A$5:$A$12=E15)*('Staffing Coverage'!$B$5:$B$12=G15),0)),"SHORT","OK")) -> SHORT
A16: 46296 | B16: =TEXT(A16,"ddd") -> Thu | C16: EMP012 | D16: =IFERROR(INDEX('Staff Master'!$B$5:$B$24,MATCH(C16,'Staff Master'!$A$5:$A$24,0)),"") -> Fatima Zahra | E16: =IFERROR(INDEX('Staff Master'!$D$5:$D$24,MATCH(C16,'Staff Master'!$A$5:$A$24,0)),"") -> Reception | F16: =IFERROR(INDEX('Staff Master'!$E$5:$E$24,MATCH(C16,'Staff Master'!$A$5:$A$24,0)),"") -> Receptionist | G16: E1 | H16: =IFERROR(INDEX('Shift Master'!$C$5:$C$16,MATCH(G16,'Shift Master'!$A$5:$A$16,0)),"") -> 0.54166667 | I16: =IFERROR(INDEX('Shift Master'!$D$5:$D$16,MATCH(G16,'Shift Master'!$A$5:$A$16,0)),"") -> 0.91666667 | J16: =IFERROR(INDEX('Shift Master'!$E$5:$E$16,MATCH(G16,'Shift Master'!$A$5:$A$16,0)),"") -> 60 | K16: =IFERROR(INDEX('Shift Master'!$G$5:$G$16,MATCH(G16,'Shift Master'!$A$5:$A$16,0)),0) -> 8 | L16: FINAL – HR CONFIRMED | M16: CONFIRMED | N16: =IF(COUNTIFS('Staffing Coverage'!$A$5:$A$12,E16,'Staffing Coverage'!$B$5:$B$12,G16)=0,"",IF(COUNTIFS($A$5:$A$10004,A16,$E$5:$E$10004,E16,$G$5:$G$10004,G16)<INDEX('Staffing Coverage'!$C$5:$C$12,MATCH(1,('Staffing Coverage'!$A$5:$A$12=E16)*('Staffing Coverage'!$B$5:$B$12=G16),0)),"SHORT","OK")) -> OK
... A624: 46326 | B624: =TEXT(A624,"ddd") -> Sat | C624: EMP020 | D624: =IFERROR(INDEX('Staff Master'!$B$5:$B$24,MATCH(C624,'Staff Master'!$A$5:$A$24,0)),"") -> Meera Pillai | E624: =IFERROR(INDEX('Staff Master'!$D$5:$D$24,MATCH(C624,'Staff Master'!$A$5:$A$24,0)),"") -> HR | F624: =IFERROR(INDEX('Staff Master'!$E$5:$E$24,MATCH(C624,'Staff Master'!$A$5:$A$24,0)),"") -> HR Executive | G624: OFF | H624: =IFERROR(INDEX('Shift Master'!$C$5:$C$16,MATCH(G624,'Shift Master'!$A$5:$A$16,0)),"") -> 0 | I624: =IFERROR(INDEX('Shift Master'!$D$5:$D$16,MATCH(G624,'Shift Master'!$A$5:$A$16,0)),"") -> 0 | J624: =IFERROR(INDEX('Shift Master'!$E$5:$E$16,MATCH(G624,'Shift Master'!$A$5:$A$16,0)),"") -> 0 | K624: =IFERROR(INDEX('Shift Master'!$G$5:$G$16,MATCH(G624,'Shift Master'!$A$5:$A$16,0)),0) -> 0 | L624: FINAL – HR CONFIRMED | M624: CONFIRMED | N624: =IF(COUNTIFS('Staffing Coverage'!$A$5:$A$12,E624,'Staffing Coverage'!$B$5:$B$12,G624)=0,"",IF(COUNTIFS($A$5:$A$10004,A624,$E$5:$E$10004,E624,$G$5:$G$10004,G624)<INDEX('Staffing Coverage'!$C$5:$C$12,MATCH(1,('Staffing Coverage'!$A$5:$A$12=E624)*('Staffing Coverage'!$B$5:$B$12=G624),0)),"SHORT","OK"))

Sheet Live Roster (Today)
A1: Live Roster
A2: FINAL – HR CONFIRMED. Shows whichever date is entered as the reference date below.
A4: Reference Date: | B4: 46301 | C4: (edit this cell — must fall within the Monthly Roster month above)
A6: Employee | B6: Department | C6: Position | D6: Shift Code | E6: Start | F6: End | G6: Status
A7: =IFERROR(INDEX('Monthly Roster'!$D$5:$D$624,MATCH(1,('Monthly Roster'!$A$5:$A$624=$B$4)*('Monthly Roster'!$C$5:$C$624='Staff Master'!$A$5),0)),"") -> Rashid Al Nuaimi | B7: ='Staff Master'!D5 -> Management | C7: ='Staff Master'!E5 -> CEO | D7: =IFERROR(INDEX('Monthly Roster'!$G$5:$G$624,MATCH(1,('Monthly Roster'!$A$5:$A$624=$B$4)*('Monthly Roster'!$C$5:$C$624='Staff Master'!$A$5),0)),"") -> M2 | E7: =IFERROR(INDEX('Monthly Roster'!$H$5:$H$624,MATCH(1,('Monthly Roster'!$A$5:$A$624=$B$4)*('Monthly Roster'!$C$5:$C$624='Staff Master'!$A$5),0)),"") -> 0.375 | F7: =IFERROR(INDEX('Monthly Roster'!$I$5:$I$624,MATCH(1,('Monthly Roster'!$A$5:$A$624=$B$4)*('Monthly Roster'!$C$5:$C$624='Staff Master'!$A$5),0)),"") -> 0.75 | G7: =IF(D7="","",IF(D7="OFF","Weekly Off",IF(OR(D7="AL",D7="SL",D7="EL",D7="UL",D7="OL",D7="PH"),"On Leave","On Duty"))) -> On Duty
A8: =IFERROR(INDEX('Monthly Roster'!$D$5:$D$624,MATCH(1,('Monthly Roster'!$A$5:$A$624=$B$4)*('Monthly Roster'!$C$5:$C$624='Staff Master'!$A$6),0)),"") -> Dr. Sara Haddad | B8: ='Staff Master'!D6 -> General Practice | C8: ='Staff Master'!E6 -> Medical Director | D8: =IFERROR(INDEX('Monthly Roster'!$G$5:$G$624,MATCH(1,('Monthly Roster'!$A$5:$A$624=$B$4)*('Monthly Roster'!$C$5:$C$624='Staff Master'!$A$6),0)),"") -> D1 | E8: =IFERROR(INDEX('Monthly Roster'!$H$5:$H$624,MATCH(1,('Monthly Roster'!$A$5:$A$624=$B$4)*('Monthly Roster'!$C$5:$C$624='Staff Master'!$A$6),0)),"") -> 0.375 | F8: =IFERROR(INDEX('Monthly Roster'!$I$5:$I$624,MATCH(1,('Monthly Roster'!$A$5:$A$624=$B$4)*('Monthly Roster'!$C$5:$C$624='Staff Master'!$A$6),0)),"") -> 0.70833333 | G8: =IF(D8="","",IF(D8="OFF","Weekly Off",IF(OR(D8="AL",D8="SL",D8="EL",D8="UL",D8="OL",D8="PH"),"On Leave","On Duty"))) -> On Duty
A9: =IFERROR(INDEX('Monthly Roster'!$D$5:$D$624,MATCH(1,('Monthly Roster'!$A$5:$A$624=$B$4)*('Monthly Roster'!$C$5:$C$624='Staff Master'!$A$7),0)),"") -> Dr. Omar Khalil | B9: ='Staff Master'!D7 -> General Practice | C9: ='Staff Master'!E7 -> Doctor | D9: =IFERROR(INDEX('Monthly Roster'!$G$5:$G$624,MATCH(1,('Monthly Roster'!$A$5:$A$624=$B$4)*('Monthly Roster'!$C$5:$C$624='Staff Master'!$A$7),0)),"") -> D1 | E9: =IFERROR(INDEX('Monthly Roster'!$H$5:$H$624,MATCH(1,('Monthly Roster'!$A$5:$A$624=$B$4)*('Monthly Roster'!$C$5:$C$624='Staff Master'!$A$7),0)),"") -> 0.375 | F9: =IFERROR(INDEX('Monthly Roster'!$I$5:$I$624,MATCH(1,('Monthly Roster'!$A$5:$A$624=$B$4)*('Monthly Roster'!$C$5:$C$624='Staff Master'!$A$7),0)),"") -> 0.70833333 | G9: =IF(D9="","",IF(D9="OFF","Weekly Off",IF(OR(D9="AL",D9="SL",D9="EL",D9="UL",D9="OL",D9="PH"),"On Leave","On Duty"))) -> On Duty
A10: =IFERROR(INDEX('Monthly Roster'!$D$5:$D$624,MATCH(1,('Monthly Roster'!$A$5:$A$624=$B$4)*('Monthly Roster'!$C$5:$C$624='Staff Master'!$A$8),0)),"") -> Dr. Lina Abboud | B10: ='Staff Master'!D8 -> Dental | C10: ='Staff Master'!E8 -> Dentist | D10: =IFERROR(INDEX('Monthly Roster'!$G$5:$G$624,MATCH(1,('Monthly Roster'!$A$5:$A$624=$B$4)*('Monthly Roster'!$C$5:$C$624='Staff Master'!$A$8),0)),"") -> D1 | E10: =IFERROR(INDEX('Monthly Roster'!$H$5:$H$624,MATCH(1,('Monthly Roster'!$A$5:$A$624=$B$4)*('Monthly Roster'!$C$5:$C$624='Staff Master'!$A$8),0)),"") -> 0.375 | F10: =IFERROR(INDEX('Monthly Roster'!$I$5:$I$624,MATCH(1,('Monthly Roster'!$A$5:$A$624=$B$4)*('Monthly Roster'!$C$5:$C$624='Staff Master'!$A$8),0)),"") -> 0.70833333 | G10: =IF(D10="","",IF(D10="OFF","Weekly Off",IF(OR(D10="AL",D10="SL",D10="EL",D10="UL",D10="OL",D10="PH"),"On Leave","On Duty"))) -> On Duty
A11: =IFERROR(INDEX('Monthly Roster'!$D$5:$D$624,MATCH(1,('Monthly Roster'!$A$5:$A$624=$B$4)*('Monthly Roster'!$C$5:$C$624='Staff Master'!$A$9),0)),"") -> Dr. Farah Idris | B11: ='Staff Master'!D9 -> Dental | C11: ='Staff Master'!E9 -> Dentist | D11: =IFERROR(INDEX('Monthly Roster'!$G$5:$G$624,MATCH(1,('Monthly Roster'!$A$5:$A$624=$B$4)*('Monthly Roster'!$C$5:$C$624='Staff Master'!$A$9),0)),"") -> D1 | E11: =IFERROR(INDEX('Monthly Roster'!$H$5:$H$624,MATCH(1,('Monthly Roster'!$A$5:$A$624=$B$4)*('Monthly Roster'!$C$5:$C$624='Staff Master'!$A$9),0)),"") -> 0.375 | F11: =IFERROR(INDEX('Monthly Roster'!$I$5:$I$624,MATCH(1,('Monthly Roster'!$A$5:$A$624=$B$4)*('Monthly Roster'!$C$5:$C$624='Staff Master'!$A$9),0)),"") -> 0.70833333 | G11: =IF(D11="","",IF(D11="OFF","Weekly Off",IF(OR(D11="AL",D11="SL",D11="EL",D11="UL",D11="OL",D11="PH"),"On Leave","On Duty"))) -> On Duty
A12: =IFERROR(INDEX('Monthly Roster'!$D$5:$D$624,MATCH(1,('Monthly Roster'!$A$5:$A$624=$B$4)*('Monthly Roster'!$C$5:$C$624='Staff Master'!$A$10),0)),"") -> Dr. Youssef Nassar | B12: ='Staff Master'!D10 -> General Practice | C12: ='Staff Master'!E10 -> General Practitioner | D12: =IFERROR(INDEX('Monthly Roster'!$G$5:$G$624,MATCH(1,('Monthly Roster'!$A$5:$A$624=$B$4)*('Monthly Roster'!$C$5:$C$624='Staff Master'!$A$10),0)),"") -> D1 | E12: =IFERROR(INDEX('Monthly Roster'!$H$5:$H$624,MATCH(1,('Monthly Roster'!$A$5:$A$624=$B$4)*('Monthly Roster'!$C$5:$C$624='Staff Master'!$A$10),0)),"") -> 0.375 | F12: =IFERROR(INDEX('Monthly Roster'!$I$5:$I$624,MATCH(1,('Monthly Roster'!$A$5:$A$624=$B$4)*('Monthly Roster'!$C$5:$C$624='Staff Master'!$A$10),0)),"") -> 0.70833333 | G12: =IF(D12="","",IF(D12="OFF","Weekly Off",IF(OR(D12="AL",D12="SL",D12="EL",D12="UL",D12="OL",D12="PH"),"On Leave","On Duty"))) -> On Duty
A13: =IFERROR(INDEX('Monthly Roster'!$D$5:$D$624,MATCH(1,('Monthly Roster'!$A$5:$A$624=$B$4)*('Monthly Roster'!$C$5:$C$624='Staff Master'!$A$11),0)),"") -> Grace Fernandez | B13: ='Staff Master'!D11 -> Nursing | C13: ='Staff Master'!E11 -> Nurse | D13: =IFERROR(INDEX('Monthly Roster'!$G$5:$G$624,MATCH(1,('Monthly Roster'!$A$5:$A$624=$B$4)*('Monthly Roster'!$C$5:$C$624='Staff Master'!$A$11),0)),"") -> M1 | E13: =IFERROR(INDEX('Monthly Roster'!$H$5:$H$624,MATCH(1,('Monthly Roster'!$A$5:$A$624=$B$4)*('Monthly Roster'!$C$5:$C$624='Staff Master'!$A$11),0)),"") -> 0.33333333 | F13: =IFERROR(INDEX('Monthly Roster'!$I$5:$I$624,MATCH(1,('Monthly Roster'!$A$5:$A$624=$B$4)*('Monthly Roster'!$C$5:$C$624='Staff Master'!$A$11),0)),"") -> 0.70833333 | G13: =IF(D13="","",IF(D13="OFF","Weekly Off",IF(OR(D13="AL",D13="SL",D13="EL",D13="UL",D13="OL",D13="PH"),"On Leave","On Duty"))) -> On Duty
A14: =IFERROR(INDEX('Monthly Roster'!$D$5:$D$624,MATCH(1,('Monthly Roster'!$A$5:$A$624=$B$4)*('Monthly Roster'!$C$5:$C$624='Staff Master'!$A$12),0)),"") -> Priya Nair | B14: ='Staff Master'!D12 -> Nursing | C14: ='Staff Master'!E12 -> Nurse | D14: =IFERROR(INDEX('Monthly Roster'!$G$5:$G$624,MATCH(1,('Monthly Roster'!$A$5:$A$624=$B$4)*('Monthly Roster'!$C$5:$C$624='Staff Master'!$A$12),0)),"") -> AL | E14: =IFERROR(INDEX('Monthly Roster'!$H$5:$H$624,MATCH(1,('Monthly Roster'!$A$5:$A$624=$B$4)*('Monthly Roster'!$C$5:$C$624='Staff Master'!$A$12),0)),"") -> 0 | F14: =IFERROR(INDEX('Monthly Roster'!$I$5:$I$624,MATCH(1,('Monthly Roster'!$A$5:$A$624=$B$4)*('Monthly Roster'!$C$5:$C$624='Staff Master'!$A$12),0)),"") -> 0 | G14: =IF(D14="","",IF(D14="OFF","Weekly Off",IF(OR(D14="AL",D14="SL",D14="EL",D14="UL",D14="OL",D14="PH"),"On Leave","On Duty"))) -> On Leave
A15: =IFERROR(INDEX('Monthly Roster'!$D$5:$D$624,MATCH(1,('Monthly Roster'!$A$5:$A$624=$B$4)*('Monthly Roster'!$C$5:$C$624='Staff Master'!$A$13),0)),"") -> Maria Santos | B15: ='Staff Master'!D13 -> Nursing | C15: ='Staff Master'!E13 -> Nurse | D15: =IFERROR(INDEX('Monthly Roster'!$G$5:$G$624,MATCH(1,('Monthly Roster'!$A$5:$A$624=$B$4)*('Monthly Roster'!$C$5:$C$624='Staff Master'!$A$13),0)),"") -> E1 | E15: =IFERROR(INDEX('Monthly Roster'!$H$5:$H$624,MATCH(1,('Monthly Roster'!$A$5:$A$624=$B$4)*('Monthly Roster'!$C$5:$C$624='Staff Master'!$A$13),0)),"") -> 0.54166667 | F15: =IFERROR(INDEX('Monthly Roster'!$I$5:$I$624,MATCH(1,('Monthly Roster'!$A$5:$A$624=$B$4)*('Monthly Roster'!$C$5:$C$624='Staff Master'!$A$13),0)),"") -> 0.91666667 | G15: =IF(D15="","",IF(D15="OFF","Weekly Off",IF(OR(D15="AL",D15="SL",D15="EL",D15="UL",D15="OL",D15="PH"),"On Leave","On Duty"))) -> On Duty
A16: =IFERROR(INDEX('Monthly Roster'!$D$5:$D$624,MATCH(1,('Monthly Roster'!$A$5:$A$624=$B$4)*('Monthly Roster'!$C$5:$C$624='Staff Master'!$A$14),0)),"") -> Aisha Al Shamsi | B16: ='Staff Master'!D14 -> Reception | C16: ='Staff Master'!E14 -> Receptionist | D16: =IFERROR(INDEX('Monthly Roster'!$G$5:$G$624,MATCH(1,('Monthly Roster'!$A$5:$A$624=$B$4)*('Monthly Roster'!$C$5:$C$624='Staff Master'!$A$14),0)),"") -> M1 | E16: =IFERROR(INDEX('Monthly Roster'!$H$5:$H$624,MATCH(1,('Monthly Roster'!$A$5:$A$624=$B$4)*('Monthly Roster'!$C$5:$C$624='Staff Master'!$A$14),0)),"") -> 0.33333333 | F16: =IFERROR(INDEX('Monthly Roster'!$I$5:$I$624,MATCH(1,('Monthly Roster'!$A$5:$A$624=$B$4)*('Monthly Roster'!$C$5:$C$624='Staff Master'!$A$14),0)),"") -> 0.70833333 | G16: =IF(D16="","",IF(D16="OFF","Weekly Off",IF(OR(D16="AL",D16="SL",D16="EL",D16="UL",D16="OL",D16="PH"),"On Leave","On Duty"))) -> On Duty
A17: =IFERROR(INDEX('Monthly Roster'!$D$5:$D$624,MATCH(1,('Monthly Roster'!$A$5:$A$624=$B$4)*('Monthly Roster'!$C$5:$C$624='Staff Master'!$A$15),0)),"") -> John Dsouza | B17: ='Staff Master'!D15 -> Reception | C17: ='Staff Master'!E15 -> Receptionist | D17: =IFERROR(INDEX('Monthly Roster'!$G$5:$G$624,MATCH(1,('Monthly Roster'!$A$5:$A$624=$B$4)*('Monthly Roster'!$C$5:$C$624='Staff Master'!$A$15),0)),"") -> OFF | E17: =IFERROR(INDEX('Monthly Roster'!$H$5:$H$624,MATCH(1,('Monthly Roster'!$A$5:$A$624=$B$4)*('Monthly Roster'!$C$5:$C$624='Staff Master'!$A$15),0)),"") -> 0 | F17: =IFERROR(INDEX('Monthly Roster'!$I$5:$I$624,MATCH(1,('Monthly Roster'!$A$5:$A$624=$B$4)*('Monthly Roster'!$C$5:$C$624='Staff Master'!$A$15),0)),"") -> 0 | G17: =IF(D17="","",IF(D17="OFF","Weekly Off",IF(OR(D17="AL",D17="SL",D17="EL",D17="UL",D17="OL",D17="PH"),"On Leave","On Duty"))) -> Weekly Off
A18: =IFERROR(INDEX('Monthly Roster'!$D$5:$D$624,MATCH(1,('Monthly Roster'!$A$5:$A$624=$B$4)*('Monthly Roster'!$C$5:$C$624='Staff Master'!$A$16),0)),"") -> Fatima Zahra | B18: ='Staff Master'!D16 -> Reception | C18: ='Staff Master'!E16 -> Receptionist | D18: =IFERROR(INDEX('Monthly Roster'!$G$5:$G$624,MATCH(1,('Monthly Roster'!$A$5:$A$624=$B$4)*('Monthly Roster'!$C$5:$C$624='Staff Master'!$A$16),0)),"") -> E1 | E18: =IFERROR(INDEX('Monthly Roster'!$H$5:$H$624,MATCH(1,('Monthly Roster'!$A$5:$A$624=$B$4)*('Monthly Roster'!$C$5:$C$624='Staff Master'!$A$16),0)),"") -> 0.54166667 | F18: =IFERROR(INDEX('Monthly Roster'!$I$5:$I$624,MATCH(1,('Monthly Roster'!$A$5:$A$624=$B$4)*('Monthly Roster'!$C$5:$C$624='Staff Master'!$A$16),0)),"") -> 0.91666667 | G18: =IF(D18="","",IF(D18="OFF","Weekly Off",IF(OR(D18="AL",D18="SL",D18="EL",D18="UL",D18="OL",D18="PH"),"On Leave","On Duty"))) -> On Duty
A19: =IFERROR(INDEX('Monthly Roster'!$D$5:$D$624,MATCH(1,('Monthly Roster'!$A$5:$A$624=$B$4)*('Monthly Roster'!$C$5:$C$624='Staff Master'!$A$17),0)),"") -> Ana Reyes | B19: ='Staff Master'!D17 -> Dental | C19: ='Staff Master'!E17 -> Dental Assistant | D19: =IFERROR(INDEX('Monthly Roster'!$G$5:$G$624,MATCH(1,('Monthly Roster'!$A$5:$A$624=$B$4)*('Monthly Roster'!$C$5:$C$624='Staff Master'!$A$17),0)),"") -> M1 | E19: =IFERROR(INDEX('Monthly Roster'!$H$5:$H$624,MATCH(1,('Monthly Roster'!$A$5:$A$624=$B$4)*('Monthly Roster'!$C$5:$C$624='Staff Master'!$A$17),0)),"") -> 0.33333333 | F19: =IFERROR(INDEX('Monthly Roster'!$I$5:$I$624,MATCH(1,('Monthly Roster'!$A$5:$A$624=$B$4)*('Monthly Roster'!$C$5:$C$624='Staff Master'!$A$17),0)),"") -> 0.70833333 | G19: =IF(D19="","",IF(D19="OFF","Weekly Off",IF(OR(D19="AL",D19="SL",D19="EL",D19="UL",D19="OL",D19="PH"),"On Leave","On Duty"))) -> On Duty
A20: =IFERROR(INDEX('Monthly Roster'!$D$5:$D$624,MATCH(1,('Monthly Roster'!$A$5:$A$624=$B$4)*('Monthly Roster'!$C$5:$C$624='Staff Master'!$A$18),0)),"") -> Noor Hassan | B20: ='Staff Master'!D18 -> Dental | C20: ='Staff Master'!E18 -> Dental Assistant | D20: =IFERROR(INDEX('Monthly Roster'!$G$5:$G$624,MATCH(1,('Monthly Roster'!$A$5:$A$624=$B$4)*('Monthly Roster'!$C$5:$C$624='Staff Master'!$A$18),0)),"") -> M2 | E20: =IFERROR(INDEX('Monthly Roster'!$H$5:$H$624,MATCH(1,('Monthly Roster'!$A$5:$A$624=$B$4)*('Monthly Roster'!$C$5:$C$624='Staff Master'!$A$18),0)),"") -> 0.375 | F20: =IFERROR(INDEX('Monthly Roster'!$I$5:$I$624,MATCH(1,('Monthly Roster'!$A$5:$A$624=$B$4)*('Monthly Roster'!$C$5:$C$624='Staff Master'!$A$18),0)),"") -> 0.75 | G20: =IF(D20="","",IF(D20="OFF","Weekly Off",IF(OR(D20="AL",D20="SL",D20="EL",D20="UL",D20="OL",D20="PH"),"On Leave","On Duty"))) -> On Duty
A21: =IFERROR(INDEX('Monthly Roster'!$D$5:$D$624,MATCH(1,('Monthly Roster'!$A$5:$A$624=$B$4)*('Monthly Roster'!$C$5:$C$624='Staff Master'!$A$19),0)),"") -> Karan Mehta | B21: ='Staff Master'!D19 -> Laser | C21: ='Staff Master'!E19 -> Laser Technician | D21: =IFERROR(INDEX('Monthly Roster'!$G$5:$G$624,MATCH(1,('Monthly Roster'!$A$5:$A$624=$B$4)*('Monthly Roster'!$C$5:$C$624='Staff Master'!$A$19),0)),"") -> M2 | E21: =IFERROR(INDEX('Monthly Roster'!$H$5:$H$624,MATCH(1,('Monthly Roster'!$A$5:$A$624=$B$4)*('Monthly Roster'!$C$5:$C$624='Staff Master'!$A$19),0)),"") -> 0.375 | F21: =IFERROR(INDEX('Monthly Roster'!$I$5:$I$624,MATCH(1,('Monthly Roster'!$A$5:$A$624=$B$4)*('Monthly Roster'!$C$5:$C$624='Staff Master'!$A$19),0)),"") -> 0.75 | G21: =IF(D21="","",IF(D21="OFF","Weekly Off",IF(OR(D21="AL",D21="SL",D21="EL",D21="UL",D21="OL",D21="PH"),"On Leave","On Duty"))) -> On Duty
A22: =IFERROR(INDEX('Monthly Roster'!$D$5:$D$624,MATCH(1,('Monthly Roster'!$A$5:$A$624=$B$4)*('Monthly Roster'!$C$5:$C$624='Staff Master'!$A$20),0)),"") -> Imran Sheikh | B22: ='Staff Master'!D20 -> Dental Laboratory | C22: ='Staff Master'!E20 -> Dental Technician | D22: =IFERROR(INDEX('Monthly Roster'!$G$5:$G$624,MATCH(1,('Monthly Roster'!$A$5:$A$624=$B$4)*('Monthly Roster'!$C$5:$C$624='Staff Master'!$A$20),0)),"") -> M1 | E22: =IFERROR(INDEX('Monthly Roster'!$H$5:$H$624,MATCH(1,('Monthly Roster'!$A$5:$A$624=$B$4)*('Monthly Roster'!$C$5:$C$624='Staff Master'!$A$20),0)),"") -> 0.33333333 | F22: =IFERROR(INDEX('Monthly Roster'!$I$5:$I$624,MATCH(1,('Monthly Roster'!$A$5:$A$624=$B$4)*('Monthly Roster'!$C$5:$C$624='Staff Master'!$A$20),0)),"") -> 0.70833333 | G22: =IF(D22="","",IF(D22="OFF","Weekly Off",IF(OR(D22="AL",D22="SL",D22="EL",D22="UL",D22="OL",D22="PH"),"On Leave","On Duty"))) -> On Duty
A23: =IFERROR(INDEX('Monthly Roster'!$D$5:$D$624,MATCH(1,('Monthly Roster'!$A$5:$A$624=$B$4)*('Monthly Roster'!$C$5:$C$624='Staff Master'!$A$21),0)),"") -> Josephine Cruz | B23: ='Staff Master'!D21 -> CSSD | C23: ='Staff Master'!E21 -> CSSD Technician | D23: =IFERROR(INDEX('Monthly Roster'!$G$5:$G$624,MATCH(1,('Monthly Roster'!$A$5:$A$624=$B$4)*('Monthly Roster'!$C$5:$C$624='Staff Master'!$A$21),0)),"") -> M1 | E23: =IFERROR(INDEX('Monthly Roster'!$H$5:$H$624,MATCH(1,('Monthly Roster'!$A$5:$A$624=$B$4)*('Monthly Roster'!$C$5:$C$624='Staff Master'!$A$21),0)),"") -> 0.33333333 | F23: =IFERROR(INDEX('Monthly Roster'!$I$5:$I$624,MATCH(1,('Monthly Roster'!$A$5:$A$624=$B$4)*('Monthly Roster'!$C$5:$C$624='Staff Master'!$A$21),0)),"") -> 0.70833333 | G23: =IF(D23="","",IF(D23="OFF","Weekly Off",IF(OR(D23="AL",D23="SL",D23="EL",D23="UL",D23="OL",D23="PH"),"On Leave","On Duty"))) -> On Duty
A24: =IFERROR(INDEX('Monthly Roster'!$D$5:$D$624,MATCH(1,('Monthly Roster'!$A$5:$A$624=$B$4)*('Monthly Roster'!$C$5:$C$624='Staff Master'!$A$22),0)),"") -> Rosalyn Tan | B24: ='Staff Master'!D22 -> Cleaning | C24: ='Staff Master'!E22 -> Cleaner | D24: =IFERROR(INDEX('Monthly Roster'!$G$5:$G$624,MATCH(1,('Monthly Roster'!$A$5:$A$624=$B$4)*('Monthly Roster'!$C$5:$C$624='Staff Master'!$A$22),0)),"") -> M1 | E24: =IFERROR(INDEX('Monthly Roster'!$H$5:$H$624,MATCH(1,('Monthly Roster'!$A$5:$A$624=$B$4)*('Monthly Roster'!$C$5:$C$624='Staff Master'!$A$22),0)),"") -> 0.33333333 | F24: =IFERROR(INDEX('Monthly Roster'!$I$5:$I$624,MATCH(1,('Monthly Roster'!$A$5:$A$624=$B$4)*('Monthly Roster'!$C$5:$C$624='Staff Master'!$A$22),0)),"") -> 0.70833333 | G24: =IF(D24="","",IF(D24="OFF","Weekly Off",IF(OR(D24="AL",D24="SL",D24="EL",D24="UL",D24="OL",D24="PH"),"On Leave","On Duty"))) -> On Duty
A25: =IFERROR(INDEX('Monthly Roster'!$D$5:$D$624,MATCH(1,('Monthly Roster'!$A$5:$A$624=$B$4)*('Monthly Roster'!$C$5:$C$624='Staff Master'!$A$23),0)),"") -> Hassan Baig | B25: ='Staff Master'!D23 -> Facilities | C25: ='Staff Master'!E23 -> Facility Manager | D25: =IFERROR(INDEX('Monthly Roster'!$G$5:$G$624,MATCH(1,('Monthly Roster'!$A$5:$A$624=$B$4)*('Monthly Roster'!$C$5:$C$624='Staff Master'!$A$23),0)),"") -> M2 | E25: =IFERROR(INDEX('Monthly Roster'!$H$5:$H$624,MATCH(1,('Monthly Roster'!$A$5:$A$624=$B$4)*('Monthly Roster'!$C$5:$C$624='Staff Master'!$A$23),0)),"") -> 0.375 | F25: =IFERROR(INDEX('Monthly Roster'!$I$5:$I$624,MATCH(1,('Monthly Roster'!$A$5:$A$624=$B$4)*('Monthly Roster'!$C$5:$C$624='Staff Master'!$A$23),0)),"") -> 0.75 | G25: =IF(D25="","",IF(D25="OFF","Weekly Off",IF(OR(D25="AL",D25="SL",D25="EL",D25="UL",D25="OL",D25="PH"),"On Leave","On Duty"))) -> On Duty
A26: =IFERROR(INDEX('Monthly Roster'!$D$5:$D$624,MATCH(1,('Monthly Roster'!$A$5:$A$624=$B$4)*('Monthly Roster'!$C$5:$C$624='Staff Master'!$A$24),0)),"") -> Meera Pillai | B26: ='Staff Master'!D24 -> HR | C26: ='Staff Master'!E24 -> HR Executive | D26: =IFERROR(INDEX('Monthly Roster'!$G$5:$G$624,MATCH(1,('Monthly Roster'!$A$5:$A$624=$B$4)*('Monthly Roster'!$C$5:$C$624='Staff Master'!$A$24),0)),"") -> M2 | E26: =IFERROR(INDEX('Monthly Roster'!$H$5:$H$624,MATCH(1,('Monthly Roster'!$A$5:$A$624=$B$4)*('Monthly Roster'!$C$5:$C$624='Staff Master'!$A$24),0)),"") -> 0.375 | F26: =IFERROR(INDEX('Monthly Roster'!$I$5:$I$624,MATCH(1,('Monthly Roster'!$A$5:$A$624=$B$4)*('Monthly Roster'!$C$5:$C$624='Staff Master'!$A$24),0)),"") -> 0.75 | G26: =IF(D26="","",IF(D26="OFF","Weekly Off",IF(OR(D26="AL",D26="SL",D26="EL",D26="UL",D26="OL",D26="PH"),"On Leave","On Duty"))) -> On Duty

Sheet Leave Register
A1: Leave / Weekly Off Register
A2: Add a row per leave request; apply the shift code to Monthly Roster once approved
A4: Employee | B4: Department | C4: Leave Type | D4: Start Date | E4: End Date | F4: Days | G4: Reason | H4: Requested By | I4: Approved By | J4: Status | K4: Remarks
A5: EMP008 | B5: Nursing | C5: Annual Leave | D5: 46300 | E5: 46305 | F5: =E5-D5+1 -> 6 | G5: Annual family travel | H5: Priya Nair | I5: Meera Pillai | J5: Approved
A6: EMP012 | B6: Reception | C6: Sick Leave | D6: 46309 | E6: 46310 | F6: =E6-D6+1 -> 2 | G6: Medical appointment | H6: Fatima Zahra | I6: Meera Pillai | J6: Approved
A7: EMP011 | B7: Reception | C7: Sick Leave | D7: 46317 | E7: 46318 | F7: =E7-D7+1 -> 2 | G7: Medical appointment | H7: John Dsouza | J7: Pending

Sheet Shift Change Requests
A1: Shift Change Requests
A2: Employee/manager requests — HR applies the approved shift to Monthly Roster
A4: Request ID | B4: Employee | C4: Department | D4: Date | E4: Current Shift | F4: Requested Shift | G4: Reason | H4: Requested By | I4: Request Date | J4: Manager Approval | K4: HR Decision | L4: HR Remarks | M4: Approved By | N4: Approval Date | O4: Status
A5: REQ-0001 | B5: Ana Reyes | C5: Dental | D5: 46303 | E5: M1 | F5: M2 | G5: Childcare drop-off changed this week | H5: Ana Reyes | I5: 46283 | J5: Pending | K5: Pending | O5: Pending Manager

Sheet Change Log
A1: Change Log / Audit Trail
A2: Append-only — never delete a row, only add new ones
A4: Change ID | B4: Date | C4: Employee | D4: Original Shift | E4: New Shift | F4: Reason | G4: Requested By | H4: Approved By | I4: Approval Time | J4: Updated By
A5: CHG-0001 | B5: 46254 | C5: Maria Santos | D5: M2 | E5: E1 | F5: Standard shift updated at joining review | G5: Dr. Sara Haddad | H5: Meera Pillai | I5: 2026-08-20 10:15 | J5: Meera Pillai
A6: CHG-0002 | B6: 46270 | C6: John Dsouza | D6: M1 | E6: M2 | F6: Approved shift-change request | G6: John Dsouza | H6: Meera Pillai | I6: 2026-09-05 09:40 | J6: Meera Pillai
A7: CHG-0003 | B7: 46289 | C7: Aisha Al Shamsi | D7: M1 | E7: SL | F7: Unplanned sick leave (emergency change) | G7: Meera Pillai | H7: Meera Pillai | I7: 2026-09-24 07:55 | J7: Meera Pillai

Sheet Monthly Summary
A1: Monthly Summary
A2: Auto-calculated from Monthly Roster for October 2026
A4: Employee | B4: Scheduled Days | C4: Working Days | D4: Weekly Off | E4: Annual Leave | F4: Sick Leave | G4: Other Leave | H4: Scheduled Hours
A5: ='Staff Master'!B5 -> Rashid Al Nuaimi | B5: =COUNTIF('Monthly Roster'!$C$5:$C$624,'Staff Master'!$A$5) -> 31 | C5: =COUNTIFS('Monthly Roster'!$C$5:$C$624,'Staff Master'!$A$5)-COUNTIFS('Monthly Roster'!$C$5:$C$624,'Staff Master'!$A$5,'Monthly Roster'!$G$5:$G$624,"OFF")-COUNTIFS('Monthly Roster'!$C$5:$C$624,'Staff Master'!$A$5,'Monthly Roster'!$G$5:$G$624,"AL")-COUNTIFS('Monthly Roster'!$C$5:$C$624,'Staff Master'!$A$5,'Monthly Roster'!$G$5:$G$624,"SL")-COUNTIFS('Monthly Roster'!$C$5:$C$624,'Staff Master'!$A$5,'Monthly Roster'!$G$5:$G$624,"EL")-COUNTIFS('Monthly Roster'!$C$5:$C$624,'Staff Master'!$A$5,'Monthly Roster'!$G$5:$G$624,"UL")-COUNTIFS('Monthly Roster'!$C$5:$C$624,'Staff Master'!$A$5,'Monthly Roster'!$G$5:$G$624,"OL")-COUNTIFS('Monthly Roster'!$C$5:$C$624,'Staff Master'!$A$5,'Monthly Roster'!$G$5:$G$624,"PH") -> 26 | D5: =COUNTIFS('Monthly Roster'!$C$5:$C$624,'Staff Master'!$A$5,'Monthly Roster'!$G$5:$G$624,"OFF") -> 5 | E5: =COUNTIFS('Monthly Roster'!$C$5:$C$624,'Staff Master'!$A$5,'Monthly Roster'!$G$5:$G$624,"AL") -> 0 | F5: =COUNTIFS('Monthly Roster'!$C$5:$C$624,'Staff Master'!$A$5,'Monthly Roster'!$G$5:$G$624,"SL") -> 0 | G5: =SUMPRODUCT(('Monthly Roster'!$C$5:$C$624='Staff Master'!$A$5)*(('Monthly Roster'!$G$5:$G$624="EL")+('Monthly Roster'!$G$5:$G$624="UL")+('Monthly Roster'!$G$5:$G$624="OL")+('Monthly Roster'!$G$5:$G$624="PH"))) -> 0 | H5: =SUMIFS('Monthly Roster'!$K$5:$K$624,'Monthly Roster'!$C$5:$C$624,'Staff Master'!$A$5) -> 208
A6: ='Staff Master'!B6 -> Dr. Sara Haddad | B6: =COUNTIF('Monthly Roster'!$C$5:$C$624,'Staff Master'!$A$6) -> 31 | C6: =COUNTIFS('Monthly Roster'!$C$5:$C$624,'Staff Master'!$A$6)-COUNTIFS('Monthly Roster'!$C$5:$C$624,'Staff Master'!$A$6,'Monthly Roster'!$G$5:$G$624,"OFF")-COUNTIFS('Monthly Roster'!$C$5:$C$624,'Staff Master'!$A$6,'Monthly Roster'!$G$5:$G$624,"AL")-COUNTIFS('Monthly Roster'!$C$5:$C$624,'Staff Master'!$A$6,'Monthly Roster'!$G$5:$G$624,"SL")-COUNTIFS('Monthly Roster'!$C$5:$C$624,'Staff Master'!$A$6,'Monthly Roster'!$G$5:$G$624,"EL")-COUNTIFS('Monthly Roster'!$C$5:$C$624,'Staff Master'!$A$6,'Monthly Roster'!$G$5:$G$624,"UL")-COUNTIFS('Monthly Roster'!$C$5:$C$624,'Staff Master'!$A$6,'Monthly Roster'!$G$5:$G$624,"OL")-COUNTIFS('Monthly Roster'!$C$5:$C$624,'Staff Master'!$A$6,'Monthly Roster'!$G$5:$G$624,"PH") -> 26 | D6: =COUNTIFS('Monthly Roster'!$C$5:$C$624,'Staff Master'!$A$6,'Monthly Roster'!$G$5:$G$624,"OFF") -> 5 | E6: =COUNTIFS('Monthly Roster'!$C$5:$C$624,'Staff Master'!$A$6,'Monthly Roster'!$G$5:$G$624,"AL") -> 0 | F6: =COUNTIFS('Monthly Roster'!$C$5:$C$624,'Staff Master'!$A$6,'Monthly Roster'!$G$5:$G$624,"SL") -> 0 | G6: =SUMPRODUCT(('Monthly Roster'!$C$5:$C$624='Staff Master'!$A$6)*(('Monthly Roster'!$G$5:$G$624="EL")+('Monthly Roster'!$G$5:$G$624="UL")+('Monthly Roster'!$G$5:$G$624="OL")+('Monthly Roster'!$G$5:$G$624="PH"))) -> 0 | H6: =SUMIFS('Monthly Roster'!$K$5:$K$624,'Monthly Roster'!$C$5:$C$624,'Staff Master'!$A$6) -> 182
A7: ='Staff Master'!B7 -> Dr. Omar Khalil | B7: =COUNTIF('Monthly Roster'!$C$5:$C$624,'Staff Master'!$A$7) -> 31 | C7: =COUNTIFS('Monthly Roster'!$C$5:$C$624,'Staff Master'!$A$7)-COUNTIFS('Monthly Roster'!$C$5:$C$624,'Staff Master'!$A$7,'Monthly Roster'!$G$5:$G$624,"OFF")-COUNTIFS('Monthly Roster'!$C$5:$C$624,'Staff Master'!$A$7,'Monthly Roster'!$G$5:$G$624,"AL")-COUNTIFS('Monthly Roster'!$C$5:$C$624,'Staff Master'!$A$7,'Monthly Roster'!$G$5:$G$624,"SL")-COUNTIFS('Monthly Roster'!$C$5:$C$624,'Staff Master'!$A$7,'Monthly Roster'!$G$5:$G$624,"EL")-COUNTIFS('Monthly Roster'!$C$5:$C$624,'Staff Master'!$A$7,'Monthly Roster'!$G$5:$G$624,"UL")-COUNTIFS('Monthly Roster'!$C$5:$C$624,'Staff Master'!$A$7,'Monthly Roster'!$G$5:$G$624,"OL")-COUNTIFS('Monthly Roster'!$C$5:$C$624,'Staff Master'!$A$7,'Monthly Roster'!$G$5:$G$624,"PH") -> 26 | D7: =COUNTIFS('Monthly Roster'!$C$5:$C$624,'Staff Master'!$A$7,'Monthly Roster'!$G$5:$G$624,"OFF") -> 5 | E7: =COUNTIFS('Monthly Roster'!$C$5:$C$624,'Staff Master'!$A$7,'Monthly Roster'!$G$5:$G$624,"AL") -> 0 | F7: =COUNTIFS('Monthly Roster'!$C$5:$C$624,'Staff Master'!$A$7,'Monthly Roster'!$G$5:$G$624,"SL") -> 0 | G7: =SUMPRODUCT(('Monthly Roster'!$C$5:$C$624='Staff Master'!$A$7)*(('Monthly Roster'!$G$5:$G$624="EL")+('Monthly Roster'!$G$5:$G$624="UL")+('Monthly Roster'!$G$5:$G$624="OL")+('Monthly Roster'!$G$5:$G$624="PH"))) -> 0 | H7: =SUMIFS('Monthly Roster'!$K$5:$K$624,'Monthly Roster'!$C$5:$C$624,'Staff Master'!$A$7) -> 182
A8: ='Staff Master'!B8 -> Dr. Lina Abboud | B8: =COUNTIF('Monthly Roster'!$C$5:$C$624,'Staff Master'!$A$8) -> 31 | C8: =COUNTIFS('Monthly Roster'!$C$5:$C$624,'Staff Master'!$A$8)-COUNTIFS('Monthly Roster'!$C$5:$C$624,'Staff Master'!$A$8,'Monthly Roster'!$G$5:$G$624,"OFF")-COUNTIFS('Monthly Roster'!$C$5:$C$624,'Staff Master'!$A$8,'Monthly Roster'!$G$5:$G$624,"AL")-COUNTIFS('Monthly Roster'!$C$5:$C$624,'Staff Master'!$A$8,'Monthly Roster'!$G$5:$G$624,"SL")-COUNTIFS('Monthly Roster'!$C$5:$C$624,'Staff Master'!$A$8,'Monthly Roster'!$G$5:$G$624,"EL")-COUNTIFS('Monthly Roster'!$C$5:$C$624,'Staff Master'!$A$8,'Monthly Roster'!$G$5:$G$624,"UL")-COUNTIFS('Monthly Roster'!$C$5:$C$624,'Staff Master'!$A$8,'Monthly Roster'!$G$5:$G$624,"OL")-COUNTIFS('Monthly Roster'!$C$5:$C$624,'Staff Master'!$A$8,'Monthly Roster'!$G$5:$G$624,"PH") -> 26 | D8: =COUNTIFS('Monthly Roster'!$C$5:$C$624,'Staff Master'!$A$8,'Monthly Roster'!$G$5:$G$624,"OFF") -> 5 | E8: =COUNTIFS('Monthly Roster'!$C$5:$C$624,'Staff Master'!$A$8,'Monthly Roster'!$G$5:$G$624,"AL") -> 0 | F8: =COUNTIFS('Monthly Roster'!$C$5:$C$624,'Staff Master'!$A$8,'Monthly Roster'!$G$5:$G$624,"SL") -> 0 | G8: =SUMPRODUCT(('Monthly Roster'!$C$5:$C$624='Staff Master'!$A$8)*(('Monthly Roster'!$G$5:$G$624="EL")+('Monthly Roster'!$G$5:$G$624="UL")+('Monthly Roster'!$G$5:$G$624="OL")+('Monthly Roster'!$G$5:$G$624="PH"))) -> 0 | H8: =SUMIFS('Monthly Roster'!$K$5:$K$624,'Monthly Roster'!$C$5:$C$624,'Staff Master'!$A$8) -> 182
A9: ='Staff Master'!B9 -> Dr. Farah Idris | B9: =COUNTIF('Monthly Roster'!$C$5:$C$624,'Staff Master'!$A$9) -> 31 | C9: =COUNTIFS('Monthly Roster'!$C$5:$C$624,'Staff Master'!$A$9)-COUNTIFS('Monthly Roster'!$C$5:$C$624,'Staff Master'!$A$9,'Monthly Roster'!$G$5:$G$624,"OFF")-COUNTIFS('Monthly Roster'!$C$5:$C$624,'Staff Master'!$A$9,'Monthly Roster'!$G$5:$G$624,"AL")-COUNTIFS('Monthly Roster'!$C$5:$C$624,'Staff Master'!$A$9,'Monthly Roster'!$G$5:$G$624,"SL")-COUNTIFS('Monthly Roster'!$C$5:$C$624,'Staff Master'!$A$9,'Monthly Roster'!$G$5:$G$624,"EL")-COUNTIFS('Monthly Roster'!$C$5:$C$624,'Staff Master'!$A$9,'Monthly Roster'!$G$5:$G$624,"UL")-COUNTIFS('Monthly Roster'!$C$5:$C$624,'Staff Master'!$A$9,'Monthly Roster'!$G$5:$G$624,"OL")-COUNTIFS('Monthly Roster'!$C$5:$C$624,'Staff Master'!$A$9,'Monthly Roster'!$G$5:$G$624,"PH") -> 27 | D9: =COUNTIFS('Monthly Roster'!$C$5:$C$624,'Staff Master'!$A$9,'Monthly Roster'!$G$5:$G$624,"OFF") -> 4 | E9: =COUNTIFS('Monthly Roster'!$C$5:$C$624,'Staff Master'!$A$9,'Monthly Roster'!$G$5:$G$624,"AL") -> 0 | F9: =COUNTIFS('Monthly Roster'!$C$5:$C$624,'Staff Master'!$A$9,'Monthly Roster'!$G$5:$G$624,"SL") -> 0 | G9: =SUMPRODUCT(('Monthly Roster'!$C$5:$C$624='Staff Master'!$A$9)*(('Monthly Roster'!$G$5:$G$624="EL")+('Monthly Roster'!$G$5:$G$624="UL")+('Monthly Roster'!$G$5:$G$624="OL")+('Monthly Roster'!$G$5:$G$624="PH"))) -> 0 | H9: =SUMIFS('Monthly Roster'!$K$5:$K$624,'Monthly Roster'!$C$5:$C$624,'Staff Master'!$A$9) -> 189
A10: ='Staff Master'!B10 -> Dr. Youssef Nassar | B10: =COUNTIF('Monthly Roster'!$C$5:$C$624,'Staff Master'!$A$10) -> 31 | C10: =COUNTIFS('Monthly Roster'!$C$5:$C$624,'Staff Master'!$A$10)-COUNTIFS('Monthly Roster'!$C$5:$C$624,'Staff Master'!$A$10,'Monthly Roster'!$G$5:$G$624,"OFF")-COUNTIFS('Monthly Roster'!$C$5:$C$624,'Staff Master'!$A$10,'Monthly Roster'!$G$5:$G$624,"AL")-COUNTIFS('Monthly Roster'!$C$5:$C$624,'Staff Master'!$A$10,'Monthly Roster'!$G$5:$G$624,"SL")-COUNTIFS('Monthly Roster'!$C$5:$C$624,'Staff Master'!$A$10,'Monthly Roster'!$G$5:$G$624,"EL")-COUNTIFS('Monthly Roster'!$C$5:$C$624,'Staff Master'!$A$10,'Monthly Roster'!$G$5:$G$624,"UL")-COUNTIFS('Monthly Roster'!$C$5:$C$624,'Staff Master'!$A$10,'Monthly Roster'!$G$5:$G$624,"OL")-COUNTIFS('Monthly Roster'!$C$5:$C$624,'Staff Master'!$A$10,'Monthly Roster'!$G$5:$G$624,"PH") -> 26 | D10: =COUNTIFS('Monthly Roster'!$C$5:$C$624,'Staff Master'!$A$10,'Monthly Roster'!$G$5:$G$624,"OFF") -> 5 | E10: =COUNTIFS('Monthly Roster'!$C$5:$C$624,'Staff Master'!$A$10,'Monthly Roster'!$G$5:$G$624,"AL") -> 0 | F10: =COUNTIFS('Monthly Roster'!$C$5:$C$624,'Staff Master'!$A$10,'Monthly Roster'!$G$5:$G$624,"SL") -> 0 | G10: =SUMPRODUCT(('Monthly Roster'!$C$5:$C$624='Staff Master'!$A$10)*(('Monthly Roster'!$G$5:$G$624="EL")+('Monthly Roster'!$G$5:$G$624="UL")+('Monthly Roster'!$G$5:$G$624="OL")+('Monthly Roster'!$G$5:$G$624="PH"))) -> 0 | H10: =SUMIFS('Monthly Roster'!$K$5:$K$624,'Monthly Roster'!$C$5:$C$624,'Staff Master'!$A$10) -> 182
A11: ='Staff Master'!B11 -> Grace Fernandez | B11: =COUNTIF('Monthly Roster'!$C$5:$C$624,'Staff Master'!$A$11) -> 31 | C11: =COUNTIFS('Monthly Roster'!$C$5:$C$624,'Staff Master'!$A$11)-COUNTIFS('Monthly Roster'!$C$5:$C$624,'Staff Master'!$A$11,'Monthly Roster'!$G$5:$G$624,"OFF")-COUNTIFS('Monthly Roster'!$C$5:$C$624,'Staff Master'!$A$11,'Monthly Roster'!$G$5:$G$624,"AL")-COUNTIFS('Monthly Roster'!$C$5:$C$624,'Staff Master'!$A$11,'Monthly Roster'!$G$5:$G$624,"SL")-COUNTIFS('Monthly Roster'!$C$5:$C$624,'Staff Master'!$A$11,'Monthly Roster'!$G$5:$G$624,"EL")-COUNTIFS('Monthly Roster'!$C$5:$C$624,'Staff Master'!$A$11,'Monthly Roster'!$G$5:$G$624,"UL")-COUNTIFS('Monthly Roster'!$C$5:$C$624,'Staff Master'!$A$11,'Monthly Roster'!$G$5:$G$624,"OL")-COUNTIFS('Monthly Roster'!$C$5:$C$624,'Staff Master'!$A$11,'Monthly Roster'!$G$5:$G$624,"PH") -> 27 | D11: =COUNTIFS('Monthly Roster'!$C$5:$C$624,'Staff Master'!$A$11,'Monthly Roster'!$G$5:$G$624,"OFF") -> 4 | E11: =COUNTIFS('Monthly Roster'!$C$5:$C$624,'Staff Master'!$A$11,'Monthly Roster'!$G$5:$G$624,"AL") -> 0 | F11: =COUNTIFS('Monthly Roster'!$C$5:$C$624,'Staff Master'!$A$11,'Monthly Roster'!$G$5:$G$624,"SL") -> 0 | G11: =SUMPRODUCT(('Monthly Roster'!$C$5:$C$624='Staff Master'!$A$11)*(('Monthly Roster'!$G$5:$G$624="EL")+('Monthly Roster'!$G$5:$G$624="UL")+('Monthly Roster'!$G$5:$G$624="OL")+('Monthly Roster'!$G$5:$G$624="PH"))) -> 0 | H11: =SUMIFS('Monthly Roster'!$K$5:$K$624,'Monthly Roster'!$C$5:$C$624,'Staff Master'!$A$11) -> 216
A12: ='Staff Master'!B12 -> Priya Nair | B12: =COUNTIF('Monthly Roster'!$C$5:$C$624,'Staff Master'!$A$12) -> 31 | C12: =COUNTIFS('Monthly Roster'!$C$5:$C$624,'Staff Master'!$A$12)-COUNTIFS('Monthly Roster'!$C$5:$C$624,'Staff Master'!$A$12,'Monthly Roster'!$G$5:$G$624,"OFF")-COUNTIFS('Monthly Roster'!$C$5:$C$624,'Staff Master'!$A$12,'Monthly Roster'!$G$5:$G$624,"AL")-COUNTIFS('Monthly Roster'!$C$5:$C$624,'Staff Master'!$A$12,'Monthly Roster'!$G$5:$G$624,"SL")-COUNTIFS('Monthly Roster'!$C$5:$C$624,'Staff Master'!$A$12,'Monthly Roster'!$G$5:$G$624,"EL")-COUNTIFS('Monthly Roster'!$C$5:$C$624,'Staff Master'!$A$12,'Monthly Roster'!$G$5:$G$624,"UL")-COUNTIFS('Monthly Roster'!$C$5:$C$624,'Staff Master'!$A$12,'Monthly Roster'!$G$5:$G$624,"OL")-COUNTIFS('Monthly Roster'!$C$5:$C$624,'Staff Master'!$A$12,'Monthly Roster'!$G$5:$G$624,"PH") -> 22 | D12: =COUNTIFS('Monthly Roster'!$C$5:$C$624,'Staff Master'!$A$12,'Monthly Roster'!$G$5:$G$624,"OFF") -> 3 | E12: =COUNTIFS('Monthly Roster'!$C$5:$C$624,'Staff Master'!$A$12,'Monthly Roster'!$G$5:$G$624,"AL") -> 6 | F12: =COUNTIFS('Monthly Roster'!$C$5:$C$624,'Staff Master'!$A$12,'Monthly Roster'!$G$5:$G$624,"SL") -> 0 | G12: =SUMPRODUCT(('Monthly Roster'!$C$5:$C$624='Staff Master'!$A$12)*(('Monthly Roster'!$G$5:$G$624="EL")+('Monthly Roster'!$G$5:$G$624="UL")+('Monthly Roster'!$G$5:$G$624="OL")+('Monthly Roster'!$G$5:$G$624="PH"))) -> 0 | H12: =SUMIFS('Monthly Roster'!$K$5:$K$624,'Monthly Roster'!$C$5:$C$624,'Staff Master'!$A$12) -> 176
A13: ='Staff Master'!B13 -> Maria Santos | B13: =COUNTIF('Monthly Roster'!$C$5:$C$624,'Staff Master'!$A$13) -> 31 | C13: =COUNTIFS('Monthly Roster'!$C$5:$C$624,'Staff Master'!$A$13)-COUNTIFS('Monthly Roster'!$C$5:$C$624,'Staff Master'!$A$13,'Monthly Roster'!$G$5:$G$624,"OFF")-COUNTIFS('Monthly Roster'!$C$5:$C$624,'Staff Master'!$A$13,'Monthly Roster'!$G$5:$G$624,"AL")-COUNTIFS('Monthly Roster'!$C$5:$C$624,'Staff Master'!$A$13,'Monthly Roster'!$G$5:$G$624,"SL")-COUNTIFS('Monthly Roster'!$C$5:$C$624,'Staff Master'!$A$13,'Monthly Roster'!$G$5:$G$624,"EL")-COUNTIFS('Monthly Roster'!$C$5:$C$624,'Staff Master'!$A$13,'Monthly Roster'!$G$5:$G$624,"UL")-COUNTIFS('Monthly Roster'!$C$5:$C$624,'Staff Master'!$A$13,'Monthly Roster'!$G$5:$G$624,"OL")-COUNTIFS('Monthly Roster'!$C$5:$C$624,'Staff Master'!$A$13,'Monthly Roster'!$G$5:$G$624,"PH") -> 26 | D13: =COUNTIFS('Monthly Roster'!$C$5:$C$624,'Staff Master'!$A$13,'Monthly Roster'!$G$5:$G$624,"OFF") -> 5 | E13: =COUNTIFS('Monthly Roster'!$C$5:$C$624,'Staff Master'!$A$13,'Monthly Roster'!$G$5:$G$624,"AL") -> 0 | F13: =COUNTIFS('Monthly Roster'!$C$5:$C$624,'Staff Master'!$A$13,'Monthly Roster'!$G$5:$G$624,"SL") -> 0 | G13: =SUMPRODUCT(('Monthly Roster'!$C$5:$C$624='Staff Master'!$A$13)*(('Monthly Roster'!$G$5:$G$624="EL")+('Monthly Roster'!$G$5:$G$624="UL")+('Monthly Roster'!$G$5:$G$624="OL")+('Monthly Roster'!$G$5:$G$624="PH"))) -> 0 | H13: =SUMIFS('Monthly Roster'!$K$5:$K$624,'Monthly Roster'!$C$5:$C$624,'Staff Master'!$A$13) -> 208
